Bounding box for latitude: 29.1344256 to 39.1344256
Bounding box for longitude: -122.669888 to -112.669888
Nearby restaurants count: 5
Distance to restaurant Alfred's Gourmet Dining: 0.9661713812022502 km
Distance to restaurant Alfred's Gourmet Dining: 0.9661713812022502 km
Distance to restaurant Alfred's Fine Eats: 0.9661713812022502 km
Distance to restaurant Harley's Circus Grill: 0.9661713812022502 km
Distance to restaurant Harley's Hysterical Diner: 0.9661713812022502 km
Filtered restaurants count (after haversine check): 5
Received request to fetch all restaurants.
Received data: {'menu_item_id': 111, 'quantity': 1}
Received request to fetch all restaurants.
Received request to fetch all restaurants.
Received request to fetch all restaurants.
Error during callback processing
Traceback (most recent call last):
  File "/home/amala/App_Academy/Projects/GothamEats/GothomEats/app/api/auth_routes.py", line 139, in callback
    id_info = id_token.verify_oauth2_token(credentials.id_token, requests.Request(), flow.client_config['web']['client_id'])
KeyError: 'web'
Error during callback processing
Traceback (most recent call last):
  File "/home/amala/App_Academy/Projects/GothamEats/GothomEats/app/api/auth_routes.py", line 139, in callback
    id_info = id_token.verify_oauth2_token(credentials.id_token, requests.Request(), flow.client_config['web']['client_id'])
KeyError: 'web'
Error during callback processing
Traceback (most recent call last):
  File "/home/amala/App_Academy/Projects/GothamEats/GothomEats/app/api/auth_routes.py", line 138, in callback
    id_info = id_token.verify_oauth2_token(credentials.id_token, requests.Request(), flow.client_config['web']['client_id'])
KeyError: 'web'
Error during callback processing
Traceback (most recent call last):
  File "/home/amala/App_Academy/Projects/GothamEats/GothomEats/app/api/auth_routes.py", line 127, in callback
    id_info = id_token.verify_oauth2_token(credentials.id_token, requests.Request(), flow.client_config['web']['client_id'])
KeyError: 'web'
Error during callback processing
Traceback (most recent call last):
  File "/home/amala/App_Academy/Projects/GothamEats/GothomEats/app/api/auth_routes.py", line 132, in callback
    id_info = id_token.verify_oauth2_token(credentials.id_token, requests.Request(), client_id)
  File "/home/amala/App_Academy/Projects/GothamEats/GothomEats/.venv/lib/python3.9/site-packages/google/oauth2/id_token.py", line 161, in verify_oauth2_token
    idinfo = verify_token(
  File "/home/amala/App_Academy/Projects/GothamEats/GothomEats/.venv/lib/python3.9/site-packages/google/oauth2/id_token.py", line 131, in verify_token
    certs = _fetch_certs(request, certs_url)
  File "/home/amala/App_Academy/Projects/GothamEats/GothomEats/.venv/lib/python3.9/site-packages/google/oauth2/id_token.py", line 97, in _fetch_certs
    response = request(certs_url, method="GET")
TypeError: 'Request' object is not callable
Using development redirect URI
Using development redirect URI
Using development redirect URI
Using development redirect URI
Error during callback processing
Traceback (most recent call last):
  File "/home/amala/App_Academy/Projects/GothamEats/GothomEats/app/api/auth_routes.py", line 135, in callback
    id_info = id_token.verify_oauth2_token(credentials.id_token, Request(), client_id)
  File "/home/amala/App_Academy/Projects/GothamEats/GothomEats/.venv/lib/python3.9/site-packages/google/oauth2/id_token.py", line 161, in verify_oauth2_token
    idinfo = verify_token(
  File "/home/amala/App_Academy/Projects/GothamEats/GothomEats/.venv/lib/python3.9/site-packages/google/oauth2/id_token.py", line 133, in verify_token
    return jwt.decode(
  File "/home/amala/App_Academy/Projects/GothamEats/GothomEats/.venv/lib/python3.9/site-packages/google/auth/jwt.py", line 302, in decode
    _verify_iat_and_exp(payload, clock_skew_in_seconds)
  File "/home/amala/App_Academy/Projects/GothamEats/GothomEats/.venv/lib/python3.9/site-packages/google/auth/jwt.py", line 216, in _verify_iat_and_exp
    raise exceptions.InvalidValue(
google.auth.exceptions.InvalidValue: Token used too early, 1701294279 < 1701294280. Check that your computer's clock is set correctly.
Using development redirect URI
Using development redirect URI
Using development redirect URI
Using development redirect URI
Error during callback processing
Traceback (most recent call last):
  File "/home/amala/App_Academy/Projects/GothamEats/GothomEats/app/api/auth_routes.py", line 135, in callback
    id_info = id_token.verify_oauth2_token(credentials.id_token, Request(), client_id)
  File "/home/amala/App_Academy/Projects/GothamEats/GothomEats/.venv/lib/python3.9/site-packages/google/oauth2/id_token.py", line 161, in verify_oauth2_token
    idinfo = verify_token(
  File "/home/amala/App_Academy/Projects/GothamEats/GothomEats/.venv/lib/python3.9/site-packages/google/oauth2/id_token.py", line 133, in verify_token
    return jwt.decode(
  File "/home/amala/App_Academy/Projects/GothamEats/GothomEats/.venv/lib/python3.9/site-packages/google/auth/jwt.py", line 302, in decode
    _verify_iat_and_exp(payload, clock_skew_in_seconds)
  File "/home/amala/App_Academy/Projects/GothamEats/GothomEats/.venv/lib/python3.9/site-packages/google/auth/jwt.py", line 216, in _verify_iat_and_exp
    raise exceptions.InvalidValue(
google.auth.exceptions.InvalidValue: Token used too early, 1701294692 < 1701294693. Check that your computer's clock is set correctly.
Using development redirect URI
Using development redirect URI
Using development redirect URI
Using development redirect URI
Error during callback processing
Traceback (most recent call last):
  File "/home/amala/App_Academy/Projects/GothamEats/GothomEats/app/api/auth_routes.py", line 135, in callback
    id_info = id_token.verify_oauth2_token(credentials.id_token, Request(), client_id)
  File "/home/amala/App_Academy/Projects/GothamEats/GothomEats/.venv/lib/python3.9/site-packages/google/oauth2/id_token.py", line 161, in verify_oauth2_token
    idinfo = verify_token(
  File "/home/amala/App_Academy/Projects/GothamEats/GothomEats/.venv/lib/python3.9/site-packages/google/oauth2/id_token.py", line 133, in verify_token
    return jwt.decode(
  File "/home/amala/App_Academy/Projects/GothamEats/GothomEats/.venv/lib/python3.9/site-packages/google/auth/jwt.py", line 302, in decode
    _verify_iat_and_exp(payload, clock_skew_in_seconds)
  File "/home/amala/App_Academy/Projects/GothamEats/GothomEats/.venv/lib/python3.9/site-packages/google/auth/jwt.py", line 216, in _verify_iat_and_exp
    raise exceptions.InvalidValue(
google.auth.exceptions.InvalidValue: Token used too early, 1701294815 < 1701294816. Check that your computer's clock is set correctly.
Using development redirect URI
Error during callback processing
Traceback (most recent call last):
  File "/home/amala/App_Academy/Projects/GothamEats/GothomEats/app/api/auth_routes.py", line 124, in callback
    flow.fetch_token(authorization_response=request.url)
  File "/home/amala/App_Academy/Projects/GothamEats/GothomEats/.venv/lib/python3.9/site-packages/google_auth_oauthlib/flow.py", line 285, in fetch_token
    return self.oauth2session.fetch_token(self.client_config["token_uri"], **kwargs)
  File "/home/amala/App_Academy/Projects/GothamEats/GothomEats/.venv/lib/python3.9/site-packages/requests_oauthlib/oauth2_session.py", line 366, in fetch_token
    self._client.parse_request_body_response(r.text, scope=self.scope)
  File "/home/amala/App_Academy/Projects/GothamEats/GothomEats/.venv/lib/python3.9/site-packages/oauthlib/oauth2/rfc6749/clients/base.py", line 427, in parse_request_body_response
    self.token = parse_token_response(body, scope=scope)
  File "/home/amala/App_Academy/Projects/GothamEats/GothomEats/.venv/lib/python3.9/site-packages/oauthlib/oauth2/rfc6749/parameters.py", line 441, in parse_token_response
    validate_token_parameters(params)
  File "/home/amala/App_Academy/Projects/GothamEats/GothomEats/.venv/lib/python3.9/site-packages/oauthlib/oauth2/rfc6749/parameters.py", line 448, in validate_token_parameters
    raise_from_error(params.get('error'), params)
  File "/home/amala/App_Academy/Projects/GothamEats/GothomEats/.venv/lib/python3.9/site-packages/oauthlib/oauth2/rfc6749/errors.py", line 399, in raise_from_error
    raise cls(**kwargs)
oauthlib.oauth2.rfc6749.errors.InvalidGrantError: (invalid_grant) Bad Request
Using development redirect URI
Using development redirect URI
Received request to fetch all restaurants.
Received data: {'menu_item_id': 37, 'quantity': 1}
Received data: {'menu_item_id': 37, 'quantity': 1}
Received request to fetch all restaurants.
Received data: {'menu_item_id': 38, 'quantity': 1}
Received request to fetch all restaurants.
Received request to fetch all restaurants.
Received data: {'menu_item_id': 185, 'quantity': 1}
Received request to fetch all restaurants.
Received data: {'menu_item_id': 186, 'quantity': 1}
Received request to fetch all restaurants.
Received data: {'menu_item_id': 38, 'quantity': 1}
Received data: {'menu_item_id': 38, 'quantity': 1}
Using development redirect URI
User successfully logged in.
Received request to fetch all restaurants.
Received data: {'menu_item_id': 186, 'quantity': 1}
Received data: {'menu_item_id': 186, 'quantity': 1}
Received data: {'menu_item_id': 185, 'quantity': 1}
Received data: {'menu_item_id': 186, 'quantity': 1}
Received request to fetch all restaurants.
Received data: {'menu_item_id': 112, 'quantity': 1}
Received request to fetch all restaurants.
Received request to fetch all restaurants.
Received data: {'menu_item_id': 561, 'quantity': 1}
Received data: {'menu_item_id': 555, 'quantity': 1}
User successfully logged in.
Received request to fetch all restaurants.
Received data: {'menu_item_id': 186, 'quantity': 1}
Received data: {'menu_item_id': 186, 'quantity': 1}
Received request to fetch all restaurants.
Received data: {'menu_item_id': 80, 'quantity': 1}
Received request to fetch all restaurants.
